
## 1. 예외 처리 도입

### 1.1. 예외 처리 도입1 - 시작

기존 자바 코드에서는 반환 값을 사용해서 오류를 처리하는 경우가 많았음. 하지만 이런 방식은 코드 가독성을 떨어뜨리고, 오류와 정상 흐름이 뒤섞여서 헷갈리게 만들었음. 그래서 자바에서는 예외(Exception) 처리를 도입해, 오류와 정상적인 코드 흐름을 명확하게 구분할 수 있게 했음.

**예제 코드:**

```java
public class Example {
    public static void main(String[] args) {
        int result = divide(10, 0);
        if (result == -1) {
            System.out.println("Error: Division by zero");
        } else {
            System.out.println("Result: " + result);
        }
    }

    public static int divide(int a, int b) {
        if (b == 0) {
            return -1; // 오류 코드 반환
        }
        return a / b;
    }
}
```

위 코드는 반환 값을 이용해 오류를 처리하는 예제임. `divide` 메서드에서 0으로 나누는 경우, -1을 반환해 오류 상황을 처리함. 하지만 이런 방식은 코드 가독성을 떨어뜨리고, 오류를 명확히 처리하기 어려움.

### 1.2. 예외 처리 도입2 - 예외 복구

예외 처리를 도입해서 발생한 오류를 복구할 수 있음. 예외를 사용하면 코드에서 예외 상황을 명확히 처리하고, 예외 발생 시 필요한 조치를 취할 수 있음.

**예제 코드:**

```java
public class Example {
    public static void main(String[] args) {
        try {
            int result = divide(10, 0);
            System.out.println("Result: " + result);
        } catch (ArithmeticException e) {
            System.out.println("Error: " + e.getMessage());
        }
    }

    public static int divide(int a, int b) {
        return a / b;
    }
}
```

위 코드는 `try-catch` 블록을 사용해서 0으로 나누는 상황에서 발생하는 `ArithmeticException`을 처리함. 예외를 처리함으로써, 오류가 발생해도 프로그램이 비정상적으로 종료되지 않고, 예외 상황을 복구할 수 있음.

### 1.3. 예외 처리 도입3 - 정상, 예외 흐름 분리

정상 흐름과 예외 흐름을 명확하게 분리해서 코드 가독성을 높일 수 있음. 정상 흐름은 `try` 블록에, 예외 흐름은 `catch` 블록에 담아 관리함.

**예제 코드:**

```java
public class Example {
    public static void main(String[] args) {
        try {
            int result = divide(10, 2);
            System.out.println("Result: " + result);
        } catch (ArithmeticException e) {
            System.out.println("Error: " + e.getMessage());
        }
    }

    public static int divide(int a, int b) {
        return a / b;
    }
}
```

이렇게 하면 코드의 정상 흐름과 예외 흐름이 명확하게 구분되어, 코드를 이해하기가 훨씬 쉬워짐.

### 1.4. 예외 처리 도입4 - 리소스 반환 문제

예외가 발생하더라도 자원을 적절히 반환해야 함. 자원은 예외 발생 여부와 상관없이 해제되어야 함. `finally` 블록을 사용해서 자원 반환을 보장할 수 있음.

**예제 코드:**

```java
public class Example {
    public static void main(String[] args) {
        try {
            int result = divide(10, 2);
            System.out.println("Result: " + result);
        } catch (ArithmeticException e) {
            System.out.println("Error: " + e.getMessage());
        } finally {
            System.out.println("Finally block executed");
        }
    }

    public static int divide(int a, int b) {
        return a / b;
    }
}
```

`finally` 블록은 예외가 발생하든 발생하지 않든 항상 실행됨. 이 블록에서 자원을 해제하면, 자원 누수를 방지할 수 있음.

### 1.5. 예외 처리 도입5 - finally

`finally` 블록은 `try` 블록이 끝난 후 항상 실행됨. 예외가 발생하더라도 반드시 실행되는 코드를 작성할 수 있음. 이를 통해 자원 해제를 보장할 수 있음.

**예제 코드:**

```java
public class Example {
    public static void main(String[] args) {
        try {
            int result = divide(10, 2);
            System.out.println("Result: " + result);
        } catch (ArithmeticException e) {
            System.out.println("Error: " + e.getMessage());
        } finally {
            System.out.println("Finally block executed");
        }
    }

    public static int divide(int a, int b) {
        return a / b;
    }
}
```

이렇게 `finally` 블록을 사용해서 예외가 발생해도 자원 반환을 보장할 수 있음.

### 1.6. 처리할 수 없는 예외와 finally

예외가 발생해도 `finally` 블록이 실행됨. 이 블록에서 자원을 해제할 수 있음. 예외를 처리하지 않더라도 자원 반납은 보장됨.

**예제 코드:**

```java
public class Example {
    public static void main(String[] args) {
        try {
            int result = divide(10, 0);
        } finally {
            System.out.println("Finally block executed");
        }
    }

    public static int divide(int a, int b) {
        return a / b;
    }
}
```

여기서는 `catch` 블록 없이 `finally` 블록만 사용했음. 예외가 발생해도 `finally` 블록이 실행됨을 보여줌.

### 1.7. try ~ finally

`try-catch` 블록 없이 `try-finally`만 사용할 수 있음. 예외를 직접 처리하지 않고 자원 해제만 보장하고 싶을 때 유용함.

**예제 코드:**

```java
public class Example {
    public static void main(String[] args) {
        try {
            int result = divide(10, 2);
        } finally {
            System.out.println("Finally block executed");
        }
    }

    public static int divide(int a, int b) {
        return a / b;
    }
}
```

이 경우 `catch` 블록이 없으므로, 예외는 호출자에게 전달되고, `finally` 블록에서 자원 해제가 이루어짐.

---

## 2. 예외 계층

### 2.1. 예외 계층1 - 시작

자바에서는 예외를 계층화해서 세밀하게 처리할 수 있음. 예외 계층을 활용하면 특정 예외를 부모 클래스에서 잡거나 던질 수 있음.

**예제 코드:**

```java
public class CustomException extends Exception {
    public CustomException(String message) {
        super(message);
    }
}

public class SubException extends CustomException {
    public SubException(String message) {
        super(message);
    }
}

public class Example {
    public static void main(String[] args) {
        try {
            throw new SubException("SubException occurred");
        } catch (CustomException e) {
            System.out.println("Caught: " + e.getMessage());
        }
    }
}
```

여기서는 `SubException`이 `CustomException`을 상속받음. 부모 클래스에서 자식 클래스의 예외를 잡을 수 있음.

### 2.2. 예외 계층2 - 활용

예외 계층을 활용하면 다양한 예외를 처리할 수 있음. 예를 들어, 연결 오류는 중요하므로 연결 관련 예외를 따로 처리하고, 나머지 예외는 공통적으로 처리할 수 있음.

**예제 코드:**

```java
public class ConnectException extends Exception {
    public ConnectException(String message) {
        super(message);
    }
}

public class Example {
    public static void main(String[] args) {
        try {
            throw new ConnectException("Connection failed");
        } catch (ConnectException e) {
            System.out.println("Caught connection exception: " + e.getMessage());
        } catch (Exception e) {
            System.out.println("Caught general exception: " + e.getMessage());
        }
    }
}
```

연결 관련 예외는 따로 처리하고, 나머지 예외는 일반적인 `Exception`으로 처리함.

### 2.3. 여러 예외를 한번에 잡는 기능

여러 예외를 `|` 연산자를 사용해서 한 번에 잡을 수 있음. 이렇게 하면 공통 부모 클래스의 기능을 사용할 수 있음.

**예제 코드:**

```java
public class Example {
    public static void main(String[] args) {
        try {
            throw new IllegalArgumentException("Invalid argument");
        } catch (IllegalArgumentException | NullPointerException e) {
            System.out.println("Caught: " + e.getMessage());
        }
    }
}
```

여기서는 `IllegalArgumentException`과 `NullPointerException`을 한 번에 처리함.

---

## 3. 실무 예외 처리 방안

### 3.1. 실무 예외 처리 방안1 - 설명

실무에서는 처리할 수 없는 예외와 복구가 불가능한 예외들이 있음. 이런 경우, 예외를 처리하지 않고 로그를 남기거나 프로그램을 종료하는 방식을 선택할 수 있음.

### 3.2. 체크 예외 사용 시나리오

체크 예외는 컴파일러가 예외 처리를 강제하는 예외임. 하지만 실무에서는 체크 예외를 사용하는 것이 코드 복잡성을 높일 수 있음. 따라서 체크 예외는 주로 외부 리소스와의 상호작용에서 사용함.

**예제 코드:**

```java
public class Example {
    public void readFile(String path) throws IOException {
        BufferedReader reader = new BufferedReader(new FileReader(path));
        String line;
        while ((line = reader.readLine()) != null) {
            System.out.println(line);
        }
    }
}
```

체크 예외는 외부 리소스 접근 시 사용함.

### 3.3. 언체크(런타임) 예외 사용 시나리오

언체크 예외는 `RuntimeException`을 상속받는 예외로, 예외 처리가 필수가 아님. 실무에서는 주로 프로그래머의 실수로 발생하는 예외들에 대해 사용함.

**예제 코드:**

```java
public class Example {
    public static void main(String[] args) {
        int result = divide(10, 0);
    }

    public static int divide(int a, int b) {
        if (b == 0) {
            throw new IllegalArgumentException("Cannot divide by zero");
        }
        return a / b;
    }
}
```

언체크 예외는 필요에 따라 처리할 수 있음.

### 3.4. 실무 예외 처리 방안2 - 구현

실무에서는 언체크 예외를 사용해 처리할 수 없는 예외들을 공통으로 처리함. 예외 발생 시 로그를 남기고, 사용자에게 의미 있는 메시지를 전달할 수 있음.

**예제 코드:**

```java
public class Example {
    public static void main(String[] args) {
        try {
            int result = divide(10, 0);
        } catch (RuntimeException e) {
            System.out.println("Error occurred: " + e.getMessage());
        }
    }

    public static int divide(int a, int b) {
        return a / b;
    }
}
```

언체크 예외를 공통으로 처리하고, 발생한 예외를 기록할 수 있음.

---

## 4. try-with-resources

자바 7에서 도입된 `try-with-resources` 구문은 외부 자원을 사용할 때 자원 누수를 방지하기 위해 도입됨. `AutoCloseable` 인터페이스를 구현한 객체를 사용할 때 유용함.

**예제 코드:**

```java
public class Example {
    public static void main(String[] args) {
        try (BufferedReader reader = new BufferedReader(new FileReader("path/to/file"))) {
            String line;
            while ((line = reader.readLine()) != null) {
                System.out.println(line);
            }
        } catch (IOException e) {
            System.out.println("Error: " + e.getMessage());
        }
    }
}
```

`try-with-resources`를 사용하면 자원이 자동으로 해제됨.

